<?xml version="1.0"?>
<!-- This URDF was automatically created by SolidWorks to URDF Exporter! Originally created by Stephen Brawner (brawner@gmail.com) 
     Commit Version: 1.5.0-0-g9aa0fdb  Build Version: 1.5.7004.21443
     For more information, please see http://wiki.ros.org/sw_urdf_exporter -->
<robot
  name="xju" xmlns:xacro="http://ros.org/wiki/xacro">
  <xacro:include filename="$(find xju_simu)/urdf/xju_model.gazebo copy.xacro"/>
  <xacro:include filename="$(find xju_simu)/urdf/common_properties.xacro"/>

  <!-- 机器人命名空间属性，由launch文件设置 -->
  <xacro:property name="ns" value="$(arg ns)" /> <!-- 机器人命名空间  -->

  <!-- Body -->
  <link
    name="${ns}_base_link">
    <inertial>
      <origin
        xyz="0 0 0"
        rpy="0 0 0" />
      <mass
        value="5" />
      <inertia
        ixx="0.13"
        ixy="0.0"
        ixz="0.0"
        iyy="0.21"
        iyz="0.0"
        izz="0.13" />
    </inertial>
    <visual>
      <origin
        xyz="0.1 0 0.25"
        rpy="0 0 0" />
      <geometry>
        <box size="0.4 0.39 0.5" />
      </geometry>
      <material name="orange" />
    </visual>
    <collision>
      <origin
        xyz="0.1 0 0.25"
        rpy="0 0 0" />
      <geometry>
        <box size="0.4 0.3 0.5" />
      </geometry>
    </collision>
  </link>

  <!-- Picture -->
  <link
    name="${ns}_pic_link">
    <visual>
      <origin
        xyz="0 0 0"
        rpy="0 0 0" />
      <geometry>
        <box size="0.4 0.39 0.001" />
      </geometry>
      <material name="orange" />
    </visual>
  </link>
  <joint
    name="${ns}_joint_pic"
    type="fixed">
    <origin
      xyz="0.1 0.0 0.5"
      rpy="0 0 0" />
    <parent
      link="${ns}_base_link" />
    <child
      link="${ns}_pic_link" />
  </joint>

  <!-- Wheel -->
  <link
    name="${ns}_universal_wheel_link">
    <inertial>
      <origin
        xyz="0 0 0"
        rpy="0 0 0" />
      <mass
        value="0.5" />
      <inertia
        ixx="9.4792E-5"
        ixy="0"
        ixz="0"
        iyy="1.5625E-4"
        iyz="0"
        izz="9.4792E-5" />
    </inertial>
    <visual>
      <origin
        xyz="0 0 0"
        rpy="0 0 0" />
      <geometry>
        <cylinder length="0.02" radius="0.025" />
      </geometry>
      <material name="black" />
    </visual>
    <collision>
      <origin
        xyz="0 0 0"
        rpy="0 0 0" />
      <geometry>
        <cylinder length="0.02" radius="0.025" />
      </geometry>
    </collision>
  </link>
  <joint
    name="${ns}_joint_uw"
    type="continuous">
    <origin
      xyz="0.2 0 -0.01"
      rpy="0 0 0" />
    <parent
      link="${ns}_base_link" />
    <child
      link="${ns}_universal_wheel_link" />
    <axis
      xyz="0 0 1" />
    <safety_controller
      k_velocity="0" />
  </joint>

  <link
    name="${ns}_front_wheel_link">
    <inertial>
      <origin
        xyz="0 0 0"
        rpy="0 0 0" />
      <mass
        value="0.5" />
      <inertia
        ixx="9.4792E-5"
        ixy="0"
        ixz="0"
        iyy="1.5625E-4"
        iyz="0"
        izz="9.4792E-5" />
    </inertial>
    <visual>
      <origin
        xyz="0 0 0"
        rpy="1.57 0 0" />
      <geometry>
        <cylinder length="0.02" radius="0.025" />
      </geometry>
      <material name="black" />
    </visual>
    <collision>
      <origin
        xyz="0 0 0"
        rpy="1.57 0 0" />
      <geometry>
        <cylinder length="0.02" radius="0.025" />
      </geometry>
    </collision>
  </link>
  <joint
    name="${ns}_joint_fw"
    type="continuous">
    <origin
      xyz="0 0 -0.035"
      rpy="0 0 0" />
    <parent
      link="${ns}_universal_wheel_link" />
    <child
      link="${ns}_front_wheel_link" />
    <axis
      xyz="0 1 0" />
    <safety_controller
      k_velocity="0" />
  </joint>

  <link
    name="${ns}_left_wheel_link">
    <inertial>
      <origin
        xyz="0 0 0"
        rpy="0 0 0" />
      <mass
        value="2" />
      <inertia
        ixx="0.002867"
        ixy="0"
        ixz="0"
        iyy="0.0049"
        iyz="0"
        izz="0.002867" />
    </inertial>
    <visual>
      <origin
        xyz="0 0 0"
        rpy="1.57 0 0" />
      <geometry>
        <cylinder length="0.05" radius="0.07" />
      </geometry>
      <material name="black" />
    </visual>
    <collision>
      <origin
        xyz="0 0 0"
        rpy="1.57 0 0" />
      <geometry>
        <cylinder length="0.05" radius="0.07" />
      </geometry>
    </collision>
  </link>
  <joint
    name="${ns}_joint_lw"
    type="continuous">
    <origin
      xyz="0 0.175 0"
      rpy="0 0 0" />
    <parent
      link="${ns}_base_link" />
    <child
      link="${ns}_left_wheel_link" />
    <axis
      xyz="0 1 0" />
    <safety_controller
      k_velocity="0" />
  </joint>

  <link
    name="${ns}_right_wheel_link">
    <inertial>
      <origin
        xyz="0 0 0"
        rpy="0 0 0" />
      <mass
        value="2" />
      <inertia
        ixx="0.002867"
        ixy="0"
        ixz="0"
        iyy="0.0049"
        iyz="0"
        izz="0.002867" />
    </inertial>
    <visual>
      <origin
        xyz="0 0 0"
        rpy="1.57 0 0" />
      <geometry>
        <cylinder length="0.05" radius="0.07" />
      </geometry>
      <material name="black" />
    </visual>
    <collision>
      <origin
        xyz="0 0 0"
        rpy="1.57 0 0" />
      <geometry>
        <cylinder length="0.05" radius="0.07" />
      </geometry>
    </collision>
  </link>
  <joint
    name="${ns}_joint_rw"
    type="continuous">
    <origin
      xyz="0 -0.175 0"
      rpy="0 0 0" />
    <parent
      link="${ns}_base_link" />
    <child
      link="${ns}_right_wheel_link" />
    <axis
      xyz="0 1 0" />
    <safety_controller
      k_velocity="0" />
  </joint>

  <!-- Imu -->
  <link name="${ns}_imu_link"/>
  <joint
    name="${ns}_joint_imu"
    type="fixed">
    <origin
      xyz="0 0 0"
      rpy="0 0 0" />
    <parent
      link="${ns}_base_link" />
    <child
      link="${ns}_imu_link" />
    <axis
      xyz="0 0 0" />
    <safety_controller
      k_velocity="0" />
  </joint>

  <!-- Lidar -->
  <link name="${ns}_laser_link">
    <visual>
      <origin
        xyz="0 0 0"
        rpy="0 0 0" />
      <geometry>
        <cylinder length="0.02" radius="0.01" />
      </geometry>
      <material name="red" />
    </visual>
  </link>
  <joint
    name="${ns}_joint_ladar"
    type="fixed">
    <origin
      xyz="0.29 0 -0.01"
      rpy="0 0 0" />
    <parent
      link="${ns}_base_link" />
    <child
      link="${ns}_laser_link" />
    <axis
      xyz="0 0 0" />
    <safety_controller
      k_velocity="0" />
  </joint>

  <link name="${ns}_top_laser_link">
    <visual>
      <origin
        xyz="0 0 0"
        rpy="0 0 0" />
      <geometry>
        <cylinder length="0.02" radius="0.01" />
      </geometry>
      <material name="red" />
    </visual>
    <visual>
      <origin
        xyz="0 0 -0.06"
        rpy="0 0 0" />
      <geometry>
        <cylinder length="0.1" radius="0.0033" />
      </geometry>
      <material name="red" />
    </visual>
  </link>
  <joint
    name="${ns}_joint_top_ladar"
    type="fixed">
    <origin
      xyz="0.1 0 0.61"
      rpy="0 0 0" />
    <parent
      link="${ns}_base_link" />
    <child
      link="${ns}_top_laser_link" />
    <axis
      xyz="0 0 0" />
    <safety_controller
      k_velocity="0" />
  </joint>

  <!-- Camera -->
  <link name="${ns}_camera_front_base"/>
  <joint name="${ns}_camera_front_base_joint" type="fixed">
    <axis xyz="0 0 0" />
    <origin xyz="0.305 0 0.495" rpy="0 0.174 0"/>
    <parent link="${ns}_base_link"/>
    <child link="${ns}_camera_front_base"/>
  </joint>
  <link name="${ns}_camera_front_link" />
  <joint name="camera_front_joint" type="fixed">
    <axis xyz="0 0 0" />
    <origin xyz="0 0 0" rpy="-1.57 0 -1.57"/>
    <parent link="${ns}_camera_front_base"/>
    <child link="${ns}_camera_front_link"/>
  </joint>

  <!-- Ultrasonic -->
    <link name="${ns}_ultra_left_front_link">
      <visual>
        <origin
          xyz="0 0 0"
          rpy="0 0 0" />
        <geometry>
          <box size="0.01 0.01 0.01" />
        </geometry>
        <material name="red" />
      </visual>
    </link>
    <joint name="${ns}_ultra_left_front_joint" type="fixed">
      <axis xyz="0 0 0" />
      <origin xyz="0.3 0.195 0.1" rpy="0 0 0.7854"/>
      <parent link="${ns}_base_link"/>
      <child link="${ns}_ultra_left_front_link"/>
    </joint>

    <link name="${ns}_ultra_left_back_link">
      <visual>
        <origin
          xyz="0 0 0"
          rpy="0 0 0" />
        <geometry>
          <box size="0.01 0.01 0.01" />
        </geometry>
        <material name="red" />
      </visual>
    </link>
    <joint name="${ns}_ultra_left_back_joint" type="fixed">
      <axis xyz="0 0 0" />
      <origin xyz="-0.1 0.195 0.1" rpy="0 0 2.3562"/>
      <parent link="${ns}_base_link"/>
      <child link="${ns}_ultra_left_back_link"/>
    </joint>

    <link name="${ns}_ultra_right_back_link">
      <visual>
        <origin
          xyz="0 0 0"
          rpy="0 0 0" />
        <geometry>
          <box size="0.01 0.01 0.01" />
        </geometry>
        <material name="red" />
      </visual>
    </link>
    <joint name="${ns}_ultra_right_back_joint" type="fixed">
      <axis xyz="0 0 0" />
      <origin xyz="-0.1 -0.195 0.1" rpy="0 0 -2.3562"/>
      <parent link="${ns}_base_link"/>
      <child link="${ns}_ultra_right_back_link"/>
    </joint>

    <link name="${ns}_ultra_right_front_link">
      <visual>
        <origin
          xyz="0 0 0"
          rpy="0 0 0" />
        <geometry>
          <box size="0.01 0.01 0.01" />
        </geometry>
        <material name="red" />
      </visual>
    </link>
    <joint name="${ns}_ultra_right_front_joint" type="fixed">
      <axis xyz="0 0 0" />
      <origin xyz="0.3 -0.195 0.1" rpy="0 0 -0.7854"/>
      <parent link="${ns}_base_link"/>
      <child link="${ns}_ultra_right_front_link"/>
    </joint>
</robot>
